[2022-05-31 20:05:18,946] {taskinstance.py:1037} INFO - Dependencies all met for <TaskInstance: todoist_load_to_pg.task_get_proj manual__2022-05-31T20:05:10.306532+00:00 [queued]>
[2022-05-31 20:05:18,958] {taskinstance.py:1037} INFO - Dependencies all met for <TaskInstance: todoist_load_to_pg.task_get_proj manual__2022-05-31T20:05:10.306532+00:00 [queued]>
[2022-05-31 20:05:18,960] {taskinstance.py:1243} INFO - 
--------------------------------------------------------------------------------
[2022-05-31 20:05:18,960] {taskinstance.py:1244} INFO - Starting attempt 1 of 1
[2022-05-31 20:05:18,961] {taskinstance.py:1245} INFO - 
--------------------------------------------------------------------------------
[2022-05-31 20:05:18,974] {taskinstance.py:1264} INFO - Executing <Task(SimpleHttpOperator): task_get_proj> on 2022-05-31 20:05:10.306532+00:00
[2022-05-31 20:05:18,979] {standard_task_runner.py:52} INFO - Started process 113 to run task
[2022-05-31 20:05:18,985] {standard_task_runner.py:76} INFO - Running: ['airflow', 'tasks', 'run', 'todoist_load_to_pg', 'task_get_proj', 'manual__2022-05-31T20:05:10.306532+00:00', '--job-id', '372', '--raw', '--subdir', 'DAGS_FOLDER/todoist_load_to_pg.py', '--cfg-path', '/tmp/tmptyzqq510', '--error-file', '/tmp/tmpai4yzmp_']
[2022-05-31 20:05:18,986] {standard_task_runner.py:77} INFO - Job 372: Subtask task_get_proj
[2022-05-31 20:05:19,048] {logging_mixin.py:109} INFO - Running <TaskInstance: todoist_load_to_pg.task_get_proj manual__2022-05-31T20:05:10.306532+00:00 [running]> on host bd658c040114
[2022-05-31 20:05:19,110] {taskinstance.py:1429} INFO - Exporting the following env vars:
AIRFLOW_CTX_DAG_OWNER=emil
AIRFLOW_CTX_DAG_ID=todoist_load_to_pg
AIRFLOW_CTX_TASK_ID=task_get_proj
AIRFLOW_CTX_EXECUTION_DATE=2022-05-31T20:05:10.306532+00:00
AIRFLOW_CTX_DAG_RUN_ID=manual__2022-05-31T20:05:10.306532+00:00
[2022-05-31 20:05:19,111] {http.py:104} INFO - Calling HTTP method
[2022-05-31 20:05:19,126] {base.py:70} INFO - Using connection to: id: todo_conn. Host: https://api.todoist.com/rest/v1/, Port: None, Schema: , Login: , Password: None, extra: {}
[2022-05-31 20:05:19,129] {http.py:129} INFO - Sending 'GET' to url: https://api.todoist.com/rest/v1/
[2022-05-31 20:05:19,198] {taskinstance.py:1718} ERROR - Task failed with exception
Traceback (most recent call last):
  File "/opt/bitnami/airflow/venv/lib/python3.8/site-packages/airflow/models/taskinstance.py", line 1334, in _run_raw_task
    self._execute_task_with_callbacks(context)
  File "/opt/bitnami/airflow/venv/lib/python3.8/site-packages/airflow/models/taskinstance.py", line 1460, in _execute_task_with_callbacks
    result = self._execute_task(context, self.task)
  File "/opt/bitnami/airflow/venv/lib/python3.8/site-packages/airflow/models/taskinstance.py", line 1516, in _execute_task
    result = execute_callable(context=context)
  File "/opt/bitnami/airflow/venv/lib/python3.8/site-packages/airflow/providers/http/operators/http.py", line 106, in execute
    response = http.run(self.endpoint, self.data, self.headers, self.extra_options)
  File "/opt/bitnami/airflow/venv/lib/python3.8/site-packages/airflow/providers/http/hooks/http.py", line 130, in run
    return self.run_and_check(session, prepped_request, extra_options)
  File "/opt/bitnami/airflow/venv/lib/python3.8/site-packages/airflow/providers/http/hooks/http.py", line 180, in run_and_check
    response = session.send(prepped_request, **send_kwargs)
  File "/opt/bitnami/airflow/venv/lib/python3.8/site-packages/requests/sessions.py", line 645, in send
    r = adapter.send(request, **kwargs)
  File "/opt/bitnami/airflow/venv/lib/python3.8/site-packages/requests/adapters.py", line 440, in send
    resp = conn.urlopen(
  File "/opt/bitnami/airflow/venv/lib/python3.8/site-packages/urllib3/connectionpool.py", line 703, in urlopen
    httplib_response = self._make_request(
  File "/opt/bitnami/airflow/venv/lib/python3.8/site-packages/urllib3/connectionpool.py", line 398, in _make_request
    conn.request(method, url, **httplib_request_kw)
  File "/opt/bitnami/airflow/venv/lib/python3.8/site-packages/urllib3/connection.py", line 239, in request
    super(HTTPConnection, self).request(method, url, body=body, headers=headers)
  File "/opt/bitnami/python/lib/python3.8/http/client.py", line 1256, in request
    self._send_request(method, url, body, headers, encode_chunked)
  File "/opt/bitnami/python/lib/python3.8/http/client.py", line 1297, in _send_request
    self.putheader(hdr, value)
  File "/opt/bitnami/airflow/venv/lib/python3.8/site-packages/urllib3/connection.py", line 224, in putheader
    _HTTPConnection.putheader(self, header, *values)
  File "/opt/bitnami/python/lib/python3.8/http/client.py", line 1224, in putheader
    raise ValueError('Invalid header name %r' % (header,))
ValueError: Invalid header name b'Authorization:'
[2022-05-31 20:05:19,215] {taskinstance.py:1272} INFO - Marking task as FAILED. dag_id=todoist_load_to_pg, task_id=task_get_proj, execution_date=20220531T200510, start_date=20220531T200518, end_date=20220531T200519
[2022-05-31 20:05:19,229] {standard_task_runner.py:89} ERROR - Failed to execute job 372 for task task_get_proj
Traceback (most recent call last):
  File "/opt/bitnami/airflow/venv/lib/python3.8/site-packages/airflow/task/task_runner/standard_task_runner.py", line 85, in _start_by_fork
    args.func(args, dag=self.dag)
  File "/opt/bitnami/airflow/venv/lib/python3.8/site-packages/airflow/cli/cli_parser.py", line 48, in command
    return func(*args, **kwargs)
  File "/opt/bitnami/airflow/venv/lib/python3.8/site-packages/airflow/utils/cli.py", line 92, in wrapper
    return f(*args, **kwargs)
  File "/opt/bitnami/airflow/venv/lib/python3.8/site-packages/airflow/cli/commands/task_command.py", line 298, in task_run
    _run_task_by_selected_method(args, dag, ti)
  File "/opt/bitnami/airflow/venv/lib/python3.8/site-packages/airflow/cli/commands/task_command.py", line 107, in _run_task_by_selected_method
    _run_raw_task(args, ti)
  File "/opt/bitnami/airflow/venv/lib/python3.8/site-packages/airflow/cli/commands/task_command.py", line 180, in _run_raw_task
    ti._run_raw_task(
  File "/opt/bitnami/airflow/venv/lib/python3.8/site-packages/airflow/utils/session.py", line 70, in wrapper
    return func(*args, session=session, **kwargs)
  File "/opt/bitnami/airflow/venv/lib/python3.8/site-packages/airflow/models/taskinstance.py", line 1334, in _run_raw_task
    self._execute_task_with_callbacks(context)
  File "/opt/bitnami/airflow/venv/lib/python3.8/site-packages/airflow/models/taskinstance.py", line 1460, in _execute_task_with_callbacks
    result = self._execute_task(context, self.task)
  File "/opt/bitnami/airflow/venv/lib/python3.8/site-packages/airflow/models/taskinstance.py", line 1516, in _execute_task
    result = execute_callable(context=context)
  File "/opt/bitnami/airflow/venv/lib/python3.8/site-packages/airflow/providers/http/operators/http.py", line 106, in execute
    response = http.run(self.endpoint, self.data, self.headers, self.extra_options)
  File "/opt/bitnami/airflow/venv/lib/python3.8/site-packages/airflow/providers/http/hooks/http.py", line 130, in run
    return self.run_and_check(session, prepped_request, extra_options)
  File "/opt/bitnami/airflow/venv/lib/python3.8/site-packages/airflow/providers/http/hooks/http.py", line 180, in run_and_check
    response = session.send(prepped_request, **send_kwargs)
  File "/opt/bitnami/airflow/venv/lib/python3.8/site-packages/requests/sessions.py", line 645, in send
    r = adapter.send(request, **kwargs)
  File "/opt/bitnami/airflow/venv/lib/python3.8/site-packages/requests/adapters.py", line 440, in send
    resp = conn.urlopen(
  File "/opt/bitnami/airflow/venv/lib/python3.8/site-packages/urllib3/connectionpool.py", line 703, in urlopen
    httplib_response = self._make_request(
  File "/opt/bitnami/airflow/venv/lib/python3.8/site-packages/urllib3/connectionpool.py", line 398, in _make_request
    conn.request(method, url, **httplib_request_kw)
  File "/opt/bitnami/airflow/venv/lib/python3.8/site-packages/urllib3/connection.py", line 239, in request
    super(HTTPConnection, self).request(method, url, body=body, headers=headers)
  File "/opt/bitnami/python/lib/python3.8/http/client.py", line 1256, in request
    self._send_request(method, url, body, headers, encode_chunked)
  File "/opt/bitnami/python/lib/python3.8/http/client.py", line 1297, in _send_request
    self.putheader(hdr, value)
  File "/opt/bitnami/airflow/venv/lib/python3.8/site-packages/urllib3/connection.py", line 224, in putheader
    _HTTPConnection.putheader(self, header, *values)
  File "/opt/bitnami/python/lib/python3.8/http/client.py", line 1224, in putheader
    raise ValueError('Invalid header name %r' % (header,))
ValueError: Invalid header name b'Authorization:'
[2022-05-31 20:05:19,277] {local_task_job.py:154} INFO - Task exited with return code 1
[2022-05-31 20:05:19,351] {local_task_job.py:264} INFO - 0 downstream tasks scheduled from follow-on schedule check
