[2022-05-31 20:45:04,253] {taskinstance.py:1037} INFO - Dependencies all met for <TaskInstance: todoist_load_to_pg.task_get_proj manual__2022-05-31T20:44:59.599836+00:00 [queued]>
[2022-05-31 20:45:04,272] {taskinstance.py:1037} INFO - Dependencies all met for <TaskInstance: todoist_load_to_pg.task_get_proj manual__2022-05-31T20:44:59.599836+00:00 [queued]>
[2022-05-31 20:45:04,273] {taskinstance.py:1243} INFO - 
--------------------------------------------------------------------------------
[2022-05-31 20:45:04,274] {taskinstance.py:1244} INFO - Starting attempt 1 of 1
[2022-05-31 20:45:04,275] {taskinstance.py:1245} INFO - 
--------------------------------------------------------------------------------
[2022-05-31 20:45:04,296] {taskinstance.py:1264} INFO - Executing <Task(SimpleHttpOperator): task_get_proj> on 2022-05-31 20:44:59.599836+00:00
[2022-05-31 20:45:04,302] {standard_task_runner.py:52} INFO - Started process 145 to run task
[2022-05-31 20:45:04,311] {standard_task_runner.py:76} INFO - Running: ['airflow', 'tasks', 'run', 'todoist_load_to_pg', 'task_get_proj', 'manual__2022-05-31T20:44:59.599836+00:00', '--job-id', '388', '--raw', '--subdir', 'DAGS_FOLDER/todoist_load_to_pg.py', '--cfg-path', '/tmp/tmp0q7ptr77', '--error-file', '/tmp/tmp5ufwsbm_']
[2022-05-31 20:45:04,312] {standard_task_runner.py:77} INFO - Job 388: Subtask task_get_proj
[2022-05-31 20:45:04,390] {logging_mixin.py:109} INFO - Running <TaskInstance: todoist_load_to_pg.task_get_proj manual__2022-05-31T20:44:59.599836+00:00 [running]> on host bd658c040114
[2022-05-31 20:45:04,477] {taskinstance.py:1429} INFO - Exporting the following env vars:
AIRFLOW_CTX_DAG_OWNER=emil
AIRFLOW_CTX_DAG_ID=todoist_load_to_pg
AIRFLOW_CTX_TASK_ID=task_get_proj
AIRFLOW_CTX_EXECUTION_DATE=2022-05-31T20:44:59.599836+00:00
AIRFLOW_CTX_DAG_RUN_ID=manual__2022-05-31T20:44:59.599836+00:00
[2022-05-31 20:45:04,479] {http.py:104} INFO - Calling HTTP method
[2022-05-31 20:45:04,501] {base.py:70} INFO - Using connection to: id: todo_conn. Host: https://api.todoist.com/rest/v1/projects, Port: None, Schema: , Login: admin, Password: ***, extra: {}
[2022-05-31 20:45:04,504] {taskinstance.py:1718} ERROR - Task failed with exception
Traceback (most recent call last):
  File "/opt/bitnami/airflow/venv/lib/python3.8/site-packages/airflow/models/taskinstance.py", line 1334, in _run_raw_task
    self._execute_task_with_callbacks(context)
  File "/opt/bitnami/airflow/venv/lib/python3.8/site-packages/airflow/models/taskinstance.py", line 1460, in _execute_task_with_callbacks
    result = self._execute_task(context, self.task)
  File "/opt/bitnami/airflow/venv/lib/python3.8/site-packages/airflow/models/taskinstance.py", line 1516, in _execute_task
    result = execute_callable(context=context)
  File "/opt/bitnami/airflow/venv/lib/python3.8/site-packages/airflow/providers/http/operators/http.py", line 106, in execute
    response = http.run(self.endpoint, self.data, self.headers, self.extra_options)
  File "/opt/bitnami/airflow/venv/lib/python3.8/site-packages/airflow/providers/http/hooks/http.py", line 114, in run
    session = self.get_conn(headers)
  File "/opt/bitnami/airflow/venv/lib/python3.8/site-packages/airflow/providers/http/hooks/http.py", line 88, in get_conn
    session.headers.update(headers)
  File "/opt/bitnami/python/lib/python3.8/_collections_abc.py", line 837, in update
    for key, value in other:
ValueError: too many values to unpack (expected 2)
[2022-05-31 20:45:04,530] {taskinstance.py:1272} INFO - Marking task as FAILED. dag_id=todoist_load_to_pg, task_id=task_get_proj, execution_date=20220531T204459, start_date=20220531T204504, end_date=20220531T204504
[2022-05-31 20:45:04,559] {standard_task_runner.py:89} ERROR - Failed to execute job 388 for task task_get_proj
Traceback (most recent call last):
  File "/opt/bitnami/airflow/venv/lib/python3.8/site-packages/airflow/task/task_runner/standard_task_runner.py", line 85, in _start_by_fork
    args.func(args, dag=self.dag)
  File "/opt/bitnami/airflow/venv/lib/python3.8/site-packages/airflow/cli/cli_parser.py", line 48, in command
    return func(*args, **kwargs)
  File "/opt/bitnami/airflow/venv/lib/python3.8/site-packages/airflow/utils/cli.py", line 92, in wrapper
    return f(*args, **kwargs)
  File "/opt/bitnami/airflow/venv/lib/python3.8/site-packages/airflow/cli/commands/task_command.py", line 298, in task_run
    _run_task_by_selected_method(args, dag, ti)
  File "/opt/bitnami/airflow/venv/lib/python3.8/site-packages/airflow/cli/commands/task_command.py", line 107, in _run_task_by_selected_method
    _run_raw_task(args, ti)
  File "/opt/bitnami/airflow/venv/lib/python3.8/site-packages/airflow/cli/commands/task_command.py", line 180, in _run_raw_task
    ti._run_raw_task(
  File "/opt/bitnami/airflow/venv/lib/python3.8/site-packages/airflow/utils/session.py", line 70, in wrapper
    return func(*args, session=session, **kwargs)
  File "/opt/bitnami/airflow/venv/lib/python3.8/site-packages/airflow/models/taskinstance.py", line 1334, in _run_raw_task
    self._execute_task_with_callbacks(context)
  File "/opt/bitnami/airflow/venv/lib/python3.8/site-packages/airflow/models/taskinstance.py", line 1460, in _execute_task_with_callbacks
    result = self._execute_task(context, self.task)
  File "/opt/bitnami/airflow/venv/lib/python3.8/site-packages/airflow/models/taskinstance.py", line 1516, in _execute_task
    result = execute_callable(context=context)
  File "/opt/bitnami/airflow/venv/lib/python3.8/site-packages/airflow/providers/http/operators/http.py", line 106, in execute
    response = http.run(self.endpoint, self.data, self.headers, self.extra_options)
  File "/opt/bitnami/airflow/venv/lib/python3.8/site-packages/airflow/providers/http/hooks/http.py", line 114, in run
    session = self.get_conn(headers)
  File "/opt/bitnami/airflow/venv/lib/python3.8/site-packages/airflow/providers/http/hooks/http.py", line 88, in get_conn
    session.headers.update(headers)
  File "/opt/bitnami/python/lib/python3.8/_collections_abc.py", line 837, in update
    for key, value in other:
ValueError: too many values to unpack (expected 2)
[2022-05-31 20:45:04,617] {local_task_job.py:154} INFO - Task exited with return code 1
[2022-05-31 20:45:04,699] {local_task_job.py:264} INFO - 0 downstream tasks scheduled from follow-on schedule check
